Workbook

Sheet Read me
A1: Alignment of the extracted results for the two Hassan, Zerva & Aulet 2024 records (same paper, extracted twice)
A3: A = _Hassan et al.-2024-A Model for Brand Personality Wo.txt
A4: B = _Hassan et al.-2024-Brand Personality Word Embedding.txt
A5: Source: complete_dataset.xlsx, sheets Gemini_2_Flash and Gemini_2_5_pro. Field order and themes follow schema.txt / instructions.txt (Blocks 1-9).
A7: Status per field (comparison of A with B within one model):
A8: Identical = same items after lower-casing, removing punctuation and the "(n)" occurrence counts
A9: Similar = similarity of 0.5 or higher; Low = similarity below 0.5
A10: Only A / Only B = filled for one record, empty for the other (similarity 0)
A11: Empty in both = not filled for either record (not counted as a filled field)
A12: Not in sheet = column does not exist in that model sheet
A13: Similarity (0-1) is lexical: the highest of item-set overlap, word-set overlap and character-sequence ratio. It understates agreement for paraphrased free text.
A14: "What differs" notes were written by reading the two values side by side; for long free-text fields only the first few hundred characters were read.
... A23: "Other datasets - summary" and "Other datasets - fields" apply the same A-vs-B comparison to Summary_Insights.xlsx, UNESCO_to_Map.xlsx (Sheet1 and To Map) and Binary_encodings.csv, with fields in their original column order. In the binary encodings a 0 counts as a filled value. File-name and key columns are left out.

Sheet Per field
A1: # | B1: Theme | C1: Field | D1: Flash: status | E1: Flash: similarity | F1: Flash: what differs | G1: Flash: value A | H1: Flash: value B | I1: Pro: status | J1: Pro: similarity | K1: Pro: what differs | L1: Pro: value A | M1: Pro: value B | N1: More consistent model (A vs B) | O1: Flash vs Pro on A: status | P1: Flash vs Pro on A: similarity | Q1: Flash vs Pro on B: status | R1: Flash vs Pro on B: similarity
A2: 1 | B2: 1 Metadata | C2: title | D2: Similar | E2: 0.55 | F2: A has the full title, B only "Brand Personality Word Embedding" | G2: A Model for Brand Personality Word Embedding: The Case of UNESCO World Heritage Sites | H2: Brand Personality Word Embedding | I2: Empty in both | N2: Flash only fills | O2: Only Flash | Q2: Only Flash
A3: 2 | B3: 1 Metadata | C3: authors | D3: Identical | E3: 1 | G3: Mohamed Abdalla Elsayed Hassan; Konstantina Zerva; Silvia Aulet | H3: Mohamed Abdalla Elsayed Hassan; Konstantina Zerva; Silvia Aulet | I3: Empty in both | N3: Flash only fills | O3: Only Flash | Q3: Only Flash
A4: 3 | B4: 1 Metadata | C4: affiliations | D4: Only B | E4: 0 | F4: B: "University of Girona" | H4: University of Girona | I4: Empty in both | N4: Flash only fills | O4: Empty in both | Q4: Only Flash
A5: 4 | B5: 1 Metadata | C5: year | D5: Identical | E5: 1 | G5: 2024 | H5: 2024 | I5: Empty in both | N5: Flash only fills | O5: Only Flash | Q5: Only Flash
A6: 5 | B6: 1 Metadata | C6: publication_type | D6: Identical | E6: 1 | G6: journal article | H6: journal article | I6: Empty in both | N6: Flash only fills | O6: Only Flash | Q6: Only Flash
A7: 6 | B7: 1 Metadata | C7: venue_name | D7: Only A | E7: 0 | F7: A: "Tourism Geographies" (looks wrong for this DOI) | G7: Tourism Geographies | I7: Empty in both | N7: Flash only fills | O7: Only Flash | Q7: Empty in both
A8: 7 | B8: 1 Metadata | C8: publisher | D8: Empty in both | I8: Empty in both | O8: Empty in both | Q8: Empty in both
A9: 8 | B9: 1 Metadata | C9: doi | D9: Identical | E9: 1 | G9: https://doi.org/10.1177/00472875221147142 | H9: https://doi.org/10.1177/00472875221147142 | I9: Empty in both | N9: Flash only fills | O9: Only Flash | Q9: Only Flash
A10: 9 | B10: 1 Metadata | C10: url | D10: Identical | E10: 1 | G10: https://doi.org/10.1177/00472875221147142 | H10: https://doi.org/10.1177/00472875221147142 | I10: Empty in both | N10: Flash only fills | O10: Only Flash | Q10: Only Flash
A11: 10 | B11: 1 Metadata | C11: language | D11: Empty in both | I11: Empty in both | O11: Empty in both | Q11: Empty in both
A12: 11 | B12: 1 Metadata | C12: page_count | D12: Empty in both | I12: Empty in both | O12: Empty in both | Q12: Empty in both
A13: 12 | B13: 2 Research context | C13: cultural_heritage_domain | D13: Similar | E13: 0.66 | F13: Both have "World Heritage Site"; the second term differs | G13: World Heritage Site (WHS) (5); World Cultural and Natural Heritage (1) | H13: World Heritage Site (WHS) (7); UNESCO World Heritage Sites (WHSs) (2) | I13: Empty in both | N13: Flash only fills | O13: Only Flash | Q13: Only Flash
A14: 13 | B14: 2 Research context | C14: heritage_type | D14: Identical | E14: 1 | G14: cultural (6); natural (2); mixed (1) | H14: cultural (6); natural (2); mixed (1) | I14: Empty in both | N14: Flash only fills | O14: Only Flash | Q14: Only Flash
A15: 14 | B15: 2 Research context | C15: cultural_entities_analyzed | D15: Low | E15: 0.33 | F15: A lists six entities including the Seville sites; B only "World Heritage Sites" | G15: World Heritage Sites (WHSs) (10); tourism destinations (3); tourism attractions (4); cathedral (1); Real Alcázar (1); Archivo General de Indias in Seville (1) | H15: World Heritage Sites (WHSs) (3) | I15: Empty in both | N15: Flash only fills | O15: Only Flash | Q15: Only Flash
A16: 15 | B16: 2 Research context | C16: heritage_terms_detected | D16: Similar | E16: 0.62 | F16: Largely the same terms; A's list is longer | G16: brand personality (BP) (19); UNESCO (20); outstanding universal values (OUVs) (2); authenticity (4); integrity (4); protection (6); management (6); World Heritage (WH) (23); 1972 Convention Concerning the Protection of the World Cultural and Natural Heritage (1); WHS list (3); WHS status (2); WHS brand (2); WHS personality (5); WHS personality categories (6); WHS personality items (3); WH personality categories (10); WH personality distribution (2); WH cultural sites (1); WH concept (2); WH Convention (1); WH meanings (2); WH status (1) | H16: world heritage (2); OUVs (1); outstanding universal values (1); 1972 Convention Concerning the Protection of the World Cultural and Natural Heritage (1); Authenticity (4); Integrity (5); Protection (6); Management (6); UNESCO (16); WHS (29) | I16: Empty in both | N16: Flash only fills | O16: Only Flash | Q16: Only Flash
A17: 16 | B17: 2 Research context | C17: heritage_values_used | D17: Only A | E17: 0 | F17: A: "valuable", "universal" with quotes | G17: valuable (2) Items such as “valuable,” and “significant” refer to how valuable WHSs are—this category also includes integrity items such as “integral” and “complete.”; universal (1) This refers to the “continental” and “universal” WHS identities and types, and is present extensively in the Brief Synthesis, and Protection and Management text files.; outstanding (2) In the Criteria Description, Description and Brief Synthesis text files, these items refer to the outstanding qualities and uniqueness of WHSs, such as “outstanding” and “extraordinary.”; economic (1) The perception of authenticity and integrity adds economic value and protection (Kim et al., 2018; Nian et al., 2019). | I17: Low | J17: 0.32 | K17: Shared: economic, social, universal; A has six more terms, B adds "outstanding" | L17: economic (1); management (4); politic (1); scientific (1); social (4); spiritual (1); universal (3); use (10); value (6) | M17: outstanding (5); universal (5); economic (2); social (1) | N17: Pro | O17: Low | P17: 0.11 | Q17: Only Pro
A18: 17 | B18: 2 Research context | C18: heritage_values_discussed | D18: Low | E18: 0.43 | F18: Same first value (Social: Emotional, collective) in a different format (text vs dictionary) | G18: Social (Emotional (collective)) – The study explores the intangible meanings of World Heritage Sites (WHSs) and their potential influence on destination preferences, suggesting a connection to cultural identity and a sense of place attachment.; Aesthetical (Artistic) – The research identifies personality categories of WHSs, including 'Attractiveness,' which relates to the aesthetic qualities and originality of these sites, reflecting artistic value.; Historic (Symbolic) – The study mentions that countries try to include as many sites as possible on the WHS list, as this is seen as increasing their international pride and recognition, indicating a symbolic value related to historical significance.; Scientific (Conceptual) – The study uses a text-mining approach to extract WHS items and classify them based on their contextual similarity, employing natural language processing (NLP) and pre-trained language models, which aligns with the conceptual aspect of scientific values. | H18: {'value': 'Social: Emotional (collective)', 'reasoning': 'The study explores the intangible meanings of World Heritage Sites and their potential influence on destination preferences, suggesting a focus on cultural identity and sense of place attachment.'}; {'value': 'Economic: Entertainment', 'reasoning': 'The paper discusses the promotion of World Heritage Sites as tourism destinations and their role in attracting visitors, indicating a consideration of the entertainment value of these sites.'}; {'value': 'Political: Symbolic', 'reasoning': 'The text mentions that countries try to include as many sites as possible on the WHS list, since this is seen as increasing their international pride and recognition, indicating a symbolic value.'}; {'value': 'Historic: Historic-Artistic', 'reasoning': 'The study focuses on identifying personality categories of World Heritage Sites, which inherently involves considering their historical and artistic significance as rare or unique examples.'}; {'value': 'Aesthetical: Artistic', 'reasoning': 'The paper discusses the attractiveness of World Heritage Sites and their authenticity, suggesting a consideration of their artistic value as original products of creativity and imagination.'}; {'value': 'Scientific: Workmanship', 'reasoning': 'The study mentions the importance of protecting and preserving World Heritage Sites, implying a consideration of the workmanship involved in their creation and maintenance.'}; {'value': 'Age: Existential', 'reasoning': 'The paper explores the intangible associations with World Heritage status, which can represent memory and the lives of past generations.'} | I18: Low | J18: 0.37 | K18: A: Historic values / Historic-Artistic; B: Social values / Emotional (collective) | L18: {'primary_value': 'HISTORIC VALUES', 'secondary_value': 'Historic-Artistic', 'reasoning': "The paper focuses on 'outstanding universal values (OUVs)' and the 'uniqueness of WHSs', which aligns with the concept of being a rare or unique example of historical or artistic movements."}; {'primary_value': 'AESTHETICAL VALUES', 'secondary_value': 'Evidential', 'reasoning': "The discussion of 'authenticity' and 'originality' as perceived by visitors and defined by UNESCO relates to the site being an authentic example from a specific part of art or architectural history."}; {'primary_value': 'POLITICAL VALUES', 'secondary_value': 'Management', 'reasoning': "The paper explicitly analyzes UNESCO concepts of 'Protection and Management' and discusses how these are incorporated into the 'Responsibility' personality category, reflecting political strategies and policies for heritage."}; {'primary_value': 'ECONOMIC VALUES', 'secondary_value': 'Entertainment', 'reasoning': "The paper discusses WHSs as 'tourism destinations' and their role in attracting visitors, which directly relates to their function in the contemporary tourism market."}; {'primary_value': 'SOCIAL VALUES', 'secondary_value': 'Emotional (collective)', 'reasoning': "The paper mentions that countries seek WHS listing to increase 'international pride and recognition', which reflects the collective emotional value and cultural identity associated with these sites."} | M18: {'primary_value': 'SOCIAL VALUES', 'secondary_value': 'Emotional (collective)', 'thinking_process': 'The paper discusses how WHS listing increases "international pride and recognition" and links brand attributes to cultural values, which directly relates to collective emotional values like cultural identity and communal pride.'}; {'primary_value': 'ECONOMIC VALUES', 'secondary_value': 'Entertainment', 'thinking_process': 'The paper frames WHSs as major tourism attractions, discussing their role in attracting visitors, tourism development, and marketing strategies, which directly aligns with the definition of entertainment value in the contemporary tourism market.'}; {'primary_value': 'ECONOMIC VALUES', 'secondary_value': 'Use', 'thinking_process': 'The paper\'s focus on WHSs as active "tourism destinations" that attract visitors and contribute to tourism development clearly points to the contemporary function and utility of these sites, aligning with the definition of \'Use\' value.'}; {'primary_value': 'POLITICAL VALUES', 'secondary_value': 'Management', 'thinking_process': 'The paper details the role of UNESCO, the 1972 Convention, and national strategies for listing sites to gain recognition. It also analyzes "Protection and Management" as a core concept, fitting the definition of management value.'}; {'primary_value': 'POLITICAL VALUES', 'secondary_value': 'Symbolic', 'thinking_process': 'The paper states that countries seek WHS listing to increase "international pride and recognition," which serves as an emblematic expression of national prestige and cultural authority, aligning with the definition of symbolic political value.'}; {'primary_value': 'AESTHETICAL VALUES', 'secondary_value': 'Artistic', 'thinking_process': 'The derived "Attractiveness" personality cluster contains words like "artistic," "original," "picturesque," and "beautiful," directly reflecting the creative and imaginative qualities that define the artistic aesthetical value.'}; {'primary_value': 'AGE VALUES', 'secondary_value': 'Existential', 'thinking_process': 'The concept of World Heritage inherently represents the memory and lives of past generations, and the study identifies "ancestral" as a personality trait, directly aligning with the definition of existential age value.'} | N18: Flash | O18: Low | P18: 0.23 | Q18: Low | R18: 0.28
A19: 18 | B19: 2 Research context | C19: heritage_management_actions | D19: Similar | E19: 0.67 | F19: A adds "heritage conservation" | G19: Protection (3); Management (6); heritage Conservation (1) | H19: Protection (2); Management (2) | I19: Empty in both | N19: Flash only fills | O19: Only Flash | Q19: Only Flash
A20: 19 | B20: 2 Research context | C20: case_study_locations | D20: Empty in both | I20: Similar | J20: 0.78 | K20: A adds "all 1,121 UNESCO World Heritage Sites" | L20: all 1,121 UNESCO World Heritage Sites (WHSs); the cathedral, the Real Alcázar and the Archivo General de Indias in Seville | M20: the cathedral, the Real Alcázar and the Archivo General de Indias in Seville | N20: Pro only fills | O20: Only Pro | Q20: Only Pro
A21: 20 | B21: 2 Research context | C21: geographical_regions | D21: Similar | E21: 0.86 | F21: Same countries; A has "Asia and Pacific region", B splits it into "Asia" and "Pacific" | G21: China (1); India (1); Japan (1); France (1); Germany (1); Italy (1); Spain (1); Asia and Pacific region (2); Europe (2); Iran (1); Catalunya (1) | H21: Asia (2); Pacific (2); Europe (3); China (2); India (1); Japan (1); France (1); Germany (1); Italy (1); Spain (1); Iran (1); Catalunya (1) | I21: Similar | J21: 0.62 | K21: B adds six extra places (Macau, Nepal, West Bengal, Bangladesh and others) | L21: China; India; Japan; Asia and Pacific region; Europe; France; Germany; Italy; Spain; Iran | M21: China; India; Japan; France; Germany; Italy; Spain; Asia and Pacific region; Europe; Iran; German cultural context; Croatian brands; Macau; Nepal; West Bengal, India; Bangladesh | N21: Flash | O21: Similar | P21: 0.93 | Q21: Low | R21: 0.47
A22: 21 | B22: 2 Research context | C22: historical_time_period | D22: Empty in both | I22: Empty in both | O22: Empty in both | Q22: Empty in both
A23: 22 | B23: 2 Research context | C23: specific_event_or_incident | D23: Only A | E23: 0 | F23: A: "Covid-19 pandemic" | G23: Covid-19 pandemic (1) | I23: Only A | J23: 0 | K23: A: the 1972 World Heritage Convention | L23: 1972 Convention Concerning the Protection of the World Cultural and Natural Heritage | N23: Equal | O23: Low | P23: 0.24 | Q23: Empty in both
A24: 23 | B24: 2 Research context | C24: research_problem_statement | D24: Identical | E24: 1 | G24: Despite having received considerable academic attention, existing brand personality (BP) scales are difficult to generalize and likely need further development. | H24: Despite having received considerable academic attention, existing brand personality (BP) scales are difficult to generalize and likely need further development. | I24: Empty in both | N24: Flash only fills | O24: Only Flash | Q24: Only Flash
A25: 24 | B25: 2 Research context | C25: research_objectives | D25: Low | E25: 0.35 | F25: Same opening sentence, then the two continue differently | G25: The aim of this study was to design a novel method for constructing context driven- BP categories through the use of a multi-disciplinary approach and advances in personality studies in psychology and natural language processing. The study has two aims. The first aim is to define the mechanisms by which WHS personality categories are constructed, given the fact that brands have cultural meanings and require a way of creating their personality categories. The second aim is to show how the personality categories of WHSs are perceived differently by experts and visitors to WHSs, since it has been suggested that personality categories may be perceived differently by those who communicate the symbolic meaning of brands and the receivers of those messages (Ranfagni et al., 2016). | H25: The aim of this study was to design a novel method for constructing context driven- BP categories through the use of a multi-disciplinary approach and advances in personality studies in psychology and natural language processing. Based on a textual analysis that relies on devising hypotheses of psycholexical representation and the distributed representation of words, the aforementioned method was employed to explore World Heritage Site (WHS) personalities using information from all 1,121 UNESCO World Heritage Sites (WHSs) and 9,920 user-generated reviews on Trip Advisor. | I25: Empty in both | N25: Flash only fills | O25: Only Flash | Q25: Only Flash
A26: 25 | B26: 3 Social media data | C26: platforms_detected | D26: Similar | E26: 0.63 | F26: Both Tripadvisor; A also lists the spelling "Trip Advisor" | G26: Trip Advisor (2); Tripadvisor (11) | H26: Tripadvisor (8) | I26: Empty in both | N26: Flash only fills | O26: Only Flash | Q26: Only Flash
A27: 26 | B27: 3 Social media data | C27: data_modalities_detected | D27: Low | E27: 0.25 | F27: A: four text-related labels; B: just "text" | G27: text (1); digital text data (2); digital visitor reviews (2); digital data (1) | H27: text (10) | I27: Similar | J27: 0.5 | K27: A adds "user-generated reviews" | L27: text; user-generated reviews | M27: text | N27: Pro | O27: Low | P27: 0.42 | Q27: Identical | R27: 1
A28: 27 | B28: 3 Social media data | C28: geolocation_data_used | D28: Empty in both | I28: Empty in both | O28: Empty in both | Q28: Empty in both
A29: 28 | B29: 3 Social media data | C29: spatial_data_characteristics | D29: Empty in both | I29: Empty in both | O29: Empty in both | Q29: Empty in both
A30: 29 | B30: 3 Social media data | C30: temporal_data_characteristics | D30: Empty in both | I30: Empty in both | O30: Empty in both | Q30: Empty in both
A31: 30 | B31: 3 Social media data | C31: engagement_metrics_detected | D31: Empty in both | I31: Empty in both | O31: Empty in both | Q31: Empty in both
A32: 31 | B32: 3 Social media data | C32: metadata_fields_detected | D32: Empty in both | I32: Empty in both | O32: Empty in both | Q32: Empty in both
A33: 32 | B33: 3 Social media data | C33: dataset_total_posts | D33: Similar | E33: 0.5 | F33: Same number (9,920); A adds "individual reviews" | G33: 9,920 individual reviews (1) | H33: 9,920 | I33: Identical | J33: 1 | L33: 9,920 | M33: 9,920 | N33: Pro | O33: Similar | P33: 0.5 | Q33: Identical | R33: 1
A34: 33 | B34: 3 Social media data | C34: dataset_total_users | D34: Empty in both | I34: Empty in both | O34: Empty in both | Q34: Empty in both
A35: 34 | B35: 3 Social media data | C35: dataset_text_posts | D35: Similar | E35: 0.73 | F35: "9,920 Tripadvisor reviews" vs "9,920 individual reviews" | G35: 9,920 Tripadvisor reviews (1) | H35: 9,920 individual reviews | I35: Low | J35: 0.15 | K35: A: "9,920"; B: a full sentence with both corpora | L35: 9,920 | M35: 9,920 individual reviews from Tripadvisor and texts describing 1,121 WHSs from UNESCO | N35: Flash | O35: Similar | P35: 0.5 | Q35: Low | R35: 0.44
A36: 35 | B36: 3 Social media data | C36: dataset_images | D36: Empty in both | I36: Empty in both | O36: Empty in both | Q36: Empty in both
A37: 36 | B37: 3 Social media data | C37: dataset_videos | D37: Empty in both | I37: Empty in both | O37: Empty in both | Q37: Empty in both
A38: 37 | B38: 3 Social media data | C38: dataset_3d_objects | D38: Empty in both | I38: Empty in both | O38: Empty in both | Q38: Empty in both
A39: 38 | B39: 3 Social media data | C39: dataset_geotagged_entries | D39: Empty in both | I39: Empty in both | O39: Empty in both | Q39: Empty in both
A40: 39 | B40: 3 Social media data | C40: dataset_time_coverage | D40: Identical | E40: 1 | G40: accessed June 28, 2021 (2) | H40: accessed June 28, 2021 | I40: Similar | J40: 0.8 | K40: Same dates, reworded | L40: Data extraction in May 2020; website access date June 28, 2021. | M40: Data extracted in May 2020 and accessed on June 28, 2021. | N40: Flash | O40: Low | P40: 0.49 | Q40: Similar | R40: 0.55
...

Sheet Per theme
A1: Gemini 2 Flash: record A vs record B
A2: Theme | B2: Fields | C2: Filled | D2: Identical | E2: Similar | F2: Low | G2: Only one record | H2: Identical rate | I2: Identical or similar | J2: Mean similarity
A3: 1 Metadata | B3: =COUNTIFS('Per field'!$B$2:$B$136,$A3,'Per field'!$D$2:$D$136,"<>Not in sheet") -> 11 | C3: =D3+E3+F3+G3 -> 8 | D3: =COUNTIFS('Per field'!$B$2:$B$136,$A3,'Per field'!$D$2:$D$136,"Identical") -> 5 | E3: =COUNTIFS('Per field'!$B$2:$B$136,$A3,'Per field'!$D$2:$D$136,"Similar") -> 1 | F3: =COUNTIFS('Per field'!$B$2:$B$136,$A3,'Per field'!$D$2:$D$136,"Low") -> 0 | G3: =COUNTIFS('Per field'!$B$2:$B$136,$A3,'Per field'!$D$2:$D$136,"Only A")+COUNTIFS('Per field'!$B$2:$B$136,$A3,'Per field'!$D$2:$D$136,"Only B") -> 2 | H3: =IFERROR(D3/C3,"–") -> 0.625 | I3: =IFERROR((D3+E3)/C3,"–") -> 0.75 | J3: =IFERROR(AVERAGEIFS('Per field'!$E$2:$E$136,'Per field'!$B$2:$B$136,$A3),"–") -> 0.69375
A4: 2 Research context | B4: =COUNTIFS('Per field'!$B$2:$B$136,$A4,'Per field'!$D$2:$D$136,"<>Not in sheet") -> 13 | C4: =D4+E4+F4+G4 -> 11 | D4: =COUNTIFS('Per field'!$B$2:$B$136,$A4,'Per field'!$D$2:$D$136,"Identical") -> 2 | E4: =COUNTIFS('Per field'!$B$2:$B$136,$A4,'Per field'!$D$2:$D$136,"Similar") -> 4 | F4: =COUNTIFS('Per field'!$B$2:$B$136,$A4,'Per field'!$D$2:$D$136,"Low") -> 3 | G4: =COUNTIFS('Per field'!$B$2:$B$136,$A4,'Per field'!$D$2:$D$136,"Only A")+COUNTIFS('Per field'!$B$2:$B$136,$A4,'Per field'!$D$2:$D$136,"Only B") -> 2 | H4: =IFERROR(D4/C4,"–") -> 0.18181818 | I4: =IFERROR((D4+E4)/C4,"–") -> 0.54545455 | J4: =IFERROR(AVERAGEIFS('Per field'!$E$2:$E$136,'Per field'!$B$2:$B$136,$A4),"–") -> 0.53818182
A5: 3 Social media data | B5: =COUNTIFS('Per field'!$B$2:$B$136,$A5,'Per field'!$D$2:$D$136,"<>Not in sheet") -> 25 | C5: =D5+E5+F5+G5 -> 11 | D5: =COUNTIFS('Per field'!$B$2:$B$136,$A5,'Per field'!$D$2:$D$136,"Identical") -> 2 | E5: =COUNTIFS('Per field'!$B$2:$B$136,$A5,'Per field'!$D$2:$D$136,"Similar") -> 3 | F5: =COUNTIFS('Per field'!$B$2:$B$136,$A5,'Per field'!$D$2:$D$136,"Low") -> 5 | G5: =COUNTIFS('Per field'!$B$2:$B$136,$A5,'Per field'!$D$2:$D$136,"Only A")+COUNTIFS('Per field'!$B$2:$B$136,$A5,'Per field'!$D$2:$D$136,"Only B") -> 1 | H5: =IFERROR(D5/C5,"–") -> 0.18181818 | I5: =IFERROR((D5+E5)/C5,"–") -> 0.45454545 | J5: =IFERROR(AVERAGEIFS('Per field'!$E$2:$E$136,'Per field'!$B$2:$B$136,$A5),"–") -> 0.45
A6: 4 AI methodology | B6: =COUNTIFS('Per field'!$B$2:$B$136,$A6,'Per field'!$D$2:$D$136,"<>Not in sheet") -> 25 | C6: =D6+E6+F6+G6 -> 7 | D6: =COUNTIFS('Per field'!$B$2:$B$136,$A6,'Per field'!$D$2:$D$136,"Identical") -> 5 | E6: =COUNTIFS('Per field'!$B$2:$B$136,$A6,'Per field'!$D$2:$D$136,"Similar") -> 2 | F6: =COUNTIFS('Per field'!$B$2:$B$136,$A6,'Per field'!$D$2:$D$136,"Low") -> 0 | G6: =COUNTIFS('Per field'!$B$2:$B$136,$A6,'Per field'!$D$2:$D$136,"Only A")+COUNTIFS('Per field'!$B$2:$B$136,$A6,'Per field'!$D$2:$D$136,"Only B") -> 0 | H6: =IFERROR(D6/C6,"–") -> 0.71428571 | I6: =IFERROR((D6+E6)/C6,"–") -> 1 | J6: =IFERROR(AVERAGEIFS('Per field'!$E$2:$E$136,'Per field'!$B$2:$B$136,$A6),"–") -> 0.94142857
A7: 5 Graph/network | B7: =COUNTIFS('Per field'!$B$2:$B$136,$A7,'Per field'!$D$2:$D$136,"<>Not in sheet") -> 11 | C7: =D7+E7+F7+G7 -> 1 | D7: =COUNTIFS('Per field'!$B$2:$B$136,$A7,'Per field'!$D$2:$D$136,"Identical") -> 1 | E7: =COUNTIFS('Per field'!$B$2:$B$136,$A7,'Per field'!$D$2:$D$136,"Similar") -> 0 | F7: =COUNTIFS('Per field'!$B$2:$B$136,$A7,'Per field'!$D$2:$D$136,"Low") -> 0 | G7: =COUNTIFS('Per field'!$B$2:$B$136,$A7,'Per field'!$D$2:$D$136,"Only A")+COUNTIFS('Per field'!$B$2:$B$136,$A7,'Per field'!$D$2:$D$136,"Only B") -> 0 | H7: =IFERROR(D7/C7,"–") -> 1 | I7: =IFERROR((D7+E7)/C7,"–") -> 1 | J7: =IFERROR(AVERAGEIFS('Per field'!$E$2:$E$136,'Per field'!$B$2:$B$136,$A7),"–") -> 1
A8: 6 Evaluation | B8: =COUNTIFS('Per field'!$B$2:$B$136,$A8,'Per field'!$D$2:$D$136,"<>Not in sheet") -> 16 | C8: =D8+E8+F8+G8 -> 3 | D8: =COUNTIFS('Per field'!$B$2:$B$136,$A8,'Per field'!$D$2:$D$136,"Identical") -> 3 | E8: =COUNTIFS('Per field'!$B$2:$B$136,$A8,'Per field'!$D$2:$D$136,"Similar") -> 0 | F8: =COUNTIFS('Per field'!$B$2:$B$136,$A8,'Per field'!$D$2:$D$136,"Low") -> 0 | G8: =COUNTIFS('Per field'!$B$2:$B$136,$A8,'Per field'!$D$2:$D$136,"Only A")+COUNTIFS('Per field'!$B$2:$B$136,$A8,'Per field'!$D$2:$D$136,"Only B") -> 0 | H8: =IFERROR(D8/C8,"–") -> 1 | I8: =IFERROR((D8+E8)/C8,"–") -> 1 | J8: =IFERROR(AVERAGEIFS('Per field'!$E$2:$E$136,'Per field'!$B$2:$B$136,$A8),"–") -> 1
A9: 7 Findings | B9: =COUNTIFS('Per field'!$B$2:$B$136,$A9,'Per field'!$D$2:$D$136,"<>Not in sheet") -> 12 | C9: =D9+E9+F9+G9 -> 2 | D9: =COUNTIFS('Per field'!$B$2:$B$136,$A9,'Per field'!$D$2:$D$136,"Identical") -> 2 | E9: =COUNTIFS('Per field'!$B$2:$B$136,$A9,'Per field'!$D$2:$D$136,"Similar") -> 0 | F9: =COUNTIFS('Per field'!$B$2:$B$136,$A9,'Per field'!$D$2:$D$136,"Low") -> 0 | G9: =COUNTIFS('Per field'!$B$2:$B$136,$A9,'Per field'!$D$2:$D$136,"Only A")+COUNTIFS('Per field'!$B$2:$B$136,$A9,'Per field'!$D$2:$D$136,"Only B") -> 0 | H9: =IFERROR(D9/C9,"–") -> 1 | I9: =IFERROR((D9+E9)/C9,"–") -> 1 | J9: =IFERROR(AVERAGEIFS('Per field'!$E$2:$E$136,'Per field'!$B$2:$B$136,$A9),"–") -> 1
A10: 8 Ethics & reproducibility | B10: =COUNTIFS('Per field'!$B$2:$B$136,$A10,'Per field'!$D$2:$D$136,"<>Not in sheet") -> 15 | C10: =D10+E10+F10+G10 -> 3 | D10: =COUNTIFS('Per field'!$B$2:$B$136,$A10,'Per field'!$D$2:$D$136,"Identical") -> 3 | E10: =COUNTIFS('Per field'!$B$2:$B$136,$A10,'Per field'!$D$2:$D$136,"Similar") -> 0 | F10: =COUNTIFS('Per field'!$B$2:$B$136,$A10,'Per field'!$D$2:$D$136,"Low") -> 0 | G10: =COUNTIFS('Per field'!$B$2:$B$136,$A10,'Per field'!$D$2:$D$136,"Only A")+COUNTIFS('Per field'!$B$2:$B$136,$A10,'Per field'!$D$2:$D$136,"Only B") -> 0 | H10: =IFERROR(D10/C10,"–") -> 1 | I10: =IFERROR((D10+E10)/C10,"–") -> 1 | J10: =IFERROR(AVERAGEIFS('Per field'!$E$2:$E$136,'Per field'!$B$2:$B$136,$A10),"–") -> 1
A11: 9 Notes | B11: =COUNTIFS('Per field'!$B$2:$B$136,$A11,'Per field'!$D$2:$D$136,"<>Not in sheet") -> 4 | C11: =D11+E11+F11+G11 -> 1 | D11: =COUNTIFS('Per field'!$B$2:$B$136,$A11,'Per field'!$D$2:$D$136,"Identical") -> 0 | E11: =COUNTIFS('Per field'!$B$2:$B$136,$A11,'Per field'!$D$2:$D$136,"Similar") -> 0 | F11: =COUNTIFS('Per field'!$B$2:$B$136,$A11,'Per field'!$D$2:$D$136,"Low") -> 0 | G11: =COUNTIFS('Per field'!$B$2:$B$136,$A11,'Per field'!$D$2:$D$136,"Only A")+COUNTIFS('Per field'!$B$2:$B$136,$A11,'Per field'!$D$2:$D$136,"Only B") -> 1 | H11: =IFERROR(D11/C11,"–") -> 0 | I11: =IFERROR((D11+E11)/C11,"–") -> 0 | J11: =IFERROR(AVERAGEIFS('Per field'!$E$2:$E$136,'Per field'!$B$2:$B$136,$A11),"–") -> 0
A12: Not in schema | B12: =COUNTIFS('Per field'!$B$2:$B$136,$A12,'Per field'!$D$2:$D$136,"<>Not in sheet") -> 1 | C12: =D12+E12+F12+G12 -> 1 | D12: =COUNTIFS('Per field'!$B$2:$B$136,$A12,'Per field'!$D$2:$D$136,"Identical") -> 1 | E12: =COUNTIFS('Per field'!$B$2:$B$136,$A12,'Per field'!$D$2:$D$136,"Similar") -> 0 | F12: =COUNTIFS('Per field'!$B$2:$B$136,$A12,'Per field'!$D$2:$D$136,"Low") -> 0 | G12: =COUNTIFS('Per field'!$B$2:$B$136,$A12,'Per field'!$D$2:$D$136,"Only A")+COUNTIFS('Per field'!$B$2:$B$136,$A12,'Per field'!$D$2:$D$136,"Only B") -> 0 | H12: =IFERROR(D12/C12,"–") -> 1 | I12: =IFERROR((D12+E12)/C12,"–") -> 1 | J12: =IFERROR(AVERAGEIFS('Per field'!$E$2:$E$136,'Per field'!$B$2:$B$136,$A12),"–") -> 1
A13: All themes (schema fields) | B13: =SUM(B3:B11) -> 132 | C13: =SUM(C3:C11) -> 47 | D13: =SUM(D3:D11) -> 23 | E13: =SUM(E3:E11) -> 10 | F13: =SUM(F3:F11) -> 8 | G13: =SUM(G3:G11) -> 6 | H13: =IFERROR(D13/C13,"–") -> 0.4893617 | I13: =IFERROR((D13+E13)/C13,"–") -> 0.70212766 | J13: =IFERROR(SUMPRODUCT(C3:C11,J3:J11)/C13,"–") -> 0.68106383
A14: All (incl. not in schema) | B14: =SUM(B3:B12) -> 133 | C14: =SUM(C3:C12) -> 48 | D14: =SUM(D3:D12) -> 24 | E14: =SUM(E3:E12) -> 10 | F14: =SUM(F3:F12) -> 8 | G14: =SUM(G3:G12) -> 6 | H14: =IFERROR(D14/C14,"–") -> 0.5 | I14: =IFERROR((D14+E14)/C14,"–") -> 0.70833333 | J14: =IFERROR(AVERAGE('Per field'!$E$2:$E$136),"–") -> 0.68770833
A16: Gemini 2.5 Pro: record A vs record B
A17: Theme | B17: Fields | C17: Filled | D17: Identical | E17: Similar | F17: Low | G17: Only one record | H17: Identical rate | I17: Identical or similar | J17: Mean similarity
A18: 1 Metadata | B18: =COUNTIFS('Per field'!$B$2:$B$136,$A18,'Per field'!$I$2:$I$136,"<>Not in sheet") -> 11 | C18: =D18+E18+F18+G18 -> 0 | D18: =COUNTIFS('Per field'!$B$2:$B$136,$A18,'Per field'!$I$2:$I$136,"Identical") -> 0 | E18: =COUNTIFS('Per field'!$B$2:$B$136,$A18,'Per field'!$I$2:$I$136,"Similar") -> 0 | F18: =COUNTIFS('Per field'!$B$2:$B$136,$A18,'Per field'!$I$2:$I$136,"Low") -> 0 | G18: =COUNTIFS('Per field'!$B$2:$B$136,$A18,'Per field'!$I$2:$I$136,"Only A")+COUNTIFS('Per field'!$B$2:$B$136,$A18,'Per field'!$I$2:$I$136,"Only B") -> 0 | H18: =IFERROR(D18/C18,"–") -> – | I18: =IFERROR((D18+E18)/C18,"–") -> – | J18: =IFERROR(AVERAGEIFS('Per field'!$J$2:$J$136,'Per field'!$B$2:$B$136,$A18),"–") -> –
A19: 2 Research context | B19: =COUNTIFS('Per field'!$B$2:$B$136,$A19,'Per field'!$I$2:$I$136,"<>Not in sheet") -> 13 | C19: =D19+E19+F19+G19 -> 5 | D19: =COUNTIFS('Per field'!$B$2:$B$136,$A19,'Per field'!$I$2:$I$136,"Identical") -> 0 | E19: =COUNTIFS('Per field'!$B$2:$B$136,$A19,'Per field'!$I$2:$I$136,"Similar") -> 2 | F19: =COUNTIFS('Per field'!$B$2:$B$136,$A19,'Per field'!$I$2:$I$136,"Low") -> 2 | G19: =COUNTIFS('Per field'!$B$2:$B$136,$A19,'Per field'!$I$2:$I$136,"Only A")+COUNTIFS('Per field'!$B$2:$B$136,$A19,'Per field'!$I$2:$I$136,"Only B") -> 1 | H19: =IFERROR(D19/C19,"–") -> 0 | I19: =IFERROR((D19+E19)/C19,"–") -> 0.4 | J19: =IFERROR(AVERAGEIFS('Per field'!$J$2:$J$136,'Per field'!$B$2:$B$136,$A19),"–") -> 0.418
A20: 3 Social media data | B20: =COUNTIFS('Per field'!$B$2:$B$136,$A20,'Per field'!$I$2:$I$136,"<>Not in sheet") -> 25 | C20: =D20+E20+F20+G20 -> 5 | D20: =COUNTIFS('Per field'!$B$2:$B$136,$A20,'Per field'!$I$2:$I$136,"Identical") -> 1 | E20: =COUNTIFS('Per field'!$B$2:$B$136,$A20,'Per field'!$I$2:$I$136,"Similar") -> 3 | F20: =COUNTIFS('Per field'!$B$2:$B$136,$A20,'Per field'!$I$2:$I$136,"Low") -> 1 | G20: =COUNTIFS('Per field'!$B$2:$B$136,$A20,'Per field'!$I$2:$I$136,"Only A")+COUNTIFS('Per field'!$B$2:$B$136,$A20,'Per field'!$I$2:$I$136,"Only B") -> 0 | H20: =IFERROR(D20/C20,"–") -> 0.2 | I20: =IFERROR((D20+E20)/C20,"–") -> 0.8 | J20: =IFERROR(AVERAGEIFS('Per field'!$J$2:$J$136,'Per field'!$B$2:$B$136,$A20),"–") -> 0.656
A21: 4 AI methodology | B21: =COUNTIFS('Per field'!$B$2:$B$136,$A21,'Per field'!$I$2:$I$136,"<>Not in sheet") -> 25 | C21: =D21+E21+F21+G21 -> 3 | D21: =COUNTIFS('Per field'!$B$2:$B$136,$A21,'Per field'!$I$2:$I$136,"Identical") -> 0 | E21: =COUNTIFS('Per field'!$B$2:$B$136,$A21,'Per field'!$I$2:$I$136,"Similar") -> 3 | F21: =COUNTIFS('Per field'!$B$2:$B$136,$A21,'Per field'!$I$2:$I$136,"Low") -> 0 | G21: =COUNTIFS('Per field'!$B$2:$B$136,$A21,'Per field'!$I$2:$I$136,"Only A")+COUNTIFS('Per field'!$B$2:$B$136,$A21,'Per field'!$I$2:$I$136,"Only B") -> 0 | H21: =IFERROR(D21/C21,"–") -> 0 | I21: =IFERROR((D21+E21)/C21,"–") -> 1 | J21: =IFERROR(AVERAGEIFS('Per field'!$J$2:$J$136,'Per field'!$B$2:$B$136,$A21),"–") -> 0.75666667
A22: 5 Graph/network | B22: =COUNTIFS('Per field'!$B$2:$B$136,$A22,'Per field'!$I$2:$I$136,"<>Not in sheet") -> 11 | C22: =D22+E22+F22+G22 -> 0 | D22: =COUNTIFS('Per field'!$B$2:$B$136,$A22,'Per field'!$I$2:$I$136,"Identical") -> 0 | E22: =COUNTIFS('Per field'!$B$2:$B$136,$A22,'Per field'!$I$2:$I$136,"Similar") -> 0 | F22: =COUNTIFS('Per field'!$B$2:$B$136,$A22,'Per field'!$I$2:$I$136,"Low") -> 0 | G22: =COUNTIFS('Per field'!$B$2:$B$136,$A22,'Per field'!$I$2:$I$136,"Only A")+COUNTIFS('Per field'!$B$2:$B$136,$A22,'Per field'!$I$2:$I$136,"Only B") -> 0 | H22: =IFERROR(D22/C22,"–") -> – | I22: =IFERROR((D22+E22)/C22,"–") -> – | J22: =IFERROR(AVERAGEIFS('Per field'!$J$2:$J$136,'Per field'!$B$2:$B$136,$A22),"–") -> –
A23: 6 Evaluation | B23: =COUNTIFS('Per field'!$B$2:$B$136,$A23,'Per field'!$I$2:$I$136,"<>Not in sheet") -> 16 | C23: =D23+E23+F23+G23 -> 6 | D23: =COUNTIFS('Per field'!$B$2:$B$136,$A23,'Per field'!$I$2:$I$136,"Identical") -> 0 | E23: =COUNTIFS('Per field'!$B$2:$B$136,$A23,'Per field'!$I$2:$I$136,"Similar") -> 2 | F23: =COUNTIFS('Per field'!$B$2:$B$136,$A23,'Per field'!$I$2:$I$136,"Low") -> 1 | G23: =COUNTIFS('Per field'!$B$2:$B$136,$A23,'Per field'!$I$2:$I$136,"Only A")+COUNTIFS('Per field'!$B$2:$B$136,$A23,'Per field'!$I$2:$I$136,"Only B") -> 3 | H23: =IFERROR(D23/C23,"–") -> 0 | I23: =IFERROR((D23+E23)/C23,"–") -> 0.33333333 | J23: =IFERROR(AVERAGEIFS('Per field'!$J$2:$J$136,'Per field'!$B$2:$B$136,$A23),"–") -> 0.225
A24: 7 Findings | B24: =COUNTIFS('Per field'!$B$2:$B$136,$A24,'Per field'!$I$2:$I$136,"<>Not in sheet") -> 12 | C24: =D24+E24+F24+G24 -> 11 | D24: =COUNTIFS('Per field'!$B$2:$B$136,$A24,'Per field'!$I$2:$I$136,"Identical") -> 0 | E24: =COUNTIFS('Per field'!$B$2:$B$136,$A24,'Per field'!$I$2:$I$136,"Similar") -> 1 | F24: =COUNTIFS('Per field'!$B$2:$B$136,$A24,'Per field'!$I$2:$I$136,"Low") -> 10 | G24: =COUNTIFS('Per field'!$B$2:$B$136,$A24,'Per field'!$I$2:$I$136,"Only A")+COUNTIFS('Per field'!$B$2:$B$136,$A24,'Per field'!$I$2:$I$136,"Only B") -> 0 | H24: =IFERROR(D24/C24,"–") -> 0 | I24: =IFERROR((D24+E24)/C24,"–") -> 0.090909091 | J24: =IFERROR(AVERAGEIFS('Per field'!$J$2:$J$136,'Per field'!$B$2:$B$136,$A24),"–") -> 0.33363636
A25: 8 Ethics & reproducibility | B25: =COUNTIFS('Per field'!$B$2:$B$136,$A25,'Per field'!$I$2:$I$136,"<>Not in sheet") -> 15 | C25: =D25+E25+F25+G25 -> 2 | D25: =COUNTIFS('Per field'!$B$2:$B$136,$A25,'Per field'!$I$2:$I$136,"Identical") -> 1 | E25: =COUNTIFS('Per field'!$B$2:$B$136,$A25,'Per field'!$I$2:$I$136,"Similar") -> 1 | F25: =COUNTIFS('Per field'!$B$2:$B$136,$A25,'Per field'!$I$2:$I$136,"Low") -> 0 | G25: =COUNTIFS('Per field'!$B$2:$B$136,$A25,'Per field'!$I$2:$I$136,"Only A")+COUNTIFS('Per field'!$B$2:$B$136,$A25,'Per field'!$I$2:$I$136,"Only B") -> 0 | H25: =IFERROR(D25/C25,"–") -> 0.5 | I25: =IFERROR((D25+E25)/C25,"–") -> 1 | J25: =IFERROR(AVERAGEIFS('Per field'!$J$2:$J$136,'Per field'!$B$2:$B$136,$A25),"–") -> 0.925
A26: 9 Notes | B26: =COUNTIFS('Per field'!$B$2:$B$136,$A26,'Per field'!$I$2:$I$136,"<>Not in sheet") -> 4 | C26: =D26+E26+F26+G26 -> 2 | D26: =COUNTIFS('Per field'!$B$2:$B$136,$A26,'Per field'!$I$2:$I$136,"Identical") -> 0 | E26: =COUNTIFS('Per field'!$B$2:$B$136,$A26,'Per field'!$I$2:$I$136,"Similar") -> 0 | F26: =COUNTIFS('Per field'!$B$2:$B$136,$A26,'Per field'!$I$2:$I$136,"Low") -> 2 | G26: =COUNTIFS('Per field'!$B$2:$B$136,$A26,'Per field'!$I$2:$I$136,"Only A")+COUNTIFS('Per field'!$B$2:$B$136,$A26,'Per field'!$I$2:$I$136,"Only B") -> 0 | H26: =IFERROR(D26/C26,"–") -> 0 | I26: =IFERROR((D26+E26)/C26,"–") -> 0 | J26: =IFERROR(AVERAGEIFS('Per field'!$J$2:$J$136,'Per field'!$B$2:$B$136,$A26),"–") -> 0.26
A27: Not in schema | B27: =COUNTIFS('Per field'!$B$2:$B$136,$A27,'Per field'!$I$2:$I$136,"<>Not in sheet") -> 3 | C27: =D27+E27+F27+G27 -> 3 | D27: =COUNTIFS('Per field'!$B$2:$B$136,$A27,'Per field'!$I$2:$I$136,"Identical") -> 3 | E27: =COUNTIFS('Per field'!$B$2:$B$136,$A27,'Per field'!$I$2:$I$136,"Similar") -> 0 | F27: =COUNTIFS('Per field'!$B$2:$B$136,$A27,'Per field'!$I$2:$I$136,"Low") -> 0 | G27: =COUNTIFS('Per field'!$B$2:$B$136,$A27,'Per field'!$I$2:$I$136,"Only A")+COUNTIFS('Per field'!$B$2:$B$136,$A27,'Per field'!$I$2:$I$136,"Only B") -> 0 | H27: =IFERROR(D27/C27,"–") -> 1 | I27: =IFERROR((D27+E27)/C27,"–") -> 1 | J27: =IFERROR(AVERAGEIFS('Per field'!$J$2:$J$136,'Per field'!$B$2:$B$136,$A27),"–") -> 1
A28: All themes (schema fields) | B28: =SUM(B18:B26) -> 132 | C28: =SUM(C18:C26) -> 34 | D28: =SUM(D18:D26) -> 2 | E28: =SUM(E18:E26) -> 12 | F28: =SUM(F18:F26) -> 16 | G28: =SUM(G18:G26) -> 4 | H28: =IFERROR(D28/C28,"–") -> 0.058823529 | I28: =IFERROR((D28+E28)/C28,"–") -> 0.41176471 | J28: =IFERROR(SUMPRODUCT(C18:C26,J18:J26)/C28,"–") -> 0.44205882
A29: All (incl. not in schema) | B29: =SUM(B18:B27) -> 135 | C29: =SUM(C18:C27) -> 37 | D29: =SUM(D18:D27) -> 5 | E29: =SUM(E18:E27) -> 12 | F29: =SUM(F18:F27) -> 16 | G29: =SUM(G18:G27) -> 4 | H29: =IFERROR(D29/C29,"–") -> 0.13513514 | I29: =IFERROR((D29+E29)/C29,"–") -> 0.45945946 | J29: =IFERROR(AVERAGE('Per field'!$J$2:$J$136),"–") -> 0.4872973
A31: Flash vs Pro on record A
A32: Theme | B32: Fields | C32: Filled by both | D32: Identical | E32: Similar | F32: Low | G32: Only one model (excluded) | H32: Identical rate | I32: Identical or similar | J32: Mean similarity
A33: 1 Metadata | B33: =COUNTIFS('Per field'!$B$2:$B$136,$A33,'Per field'!$O$2:$O$136,"<>Not in sheet") -> 11 | C33: =D33+E33+F33 -> 0 | D33: =COUNTIFS('Per field'!$B$2:$B$136,$A33,'Per field'!$O$2:$O$136,"Identical") -> 0 | E33: =COUNTIFS('Per field'!$B$2:$B$136,$A33,'Per field'!$O$2:$O$136,"Similar") -> 0 | F33: =COUNTIFS('Per field'!$B$2:$B$136,$A33,'Per field'!$O$2:$O$136,"Low") -> 0 | G33: =COUNTIFS('Per field'!$B$2:$B$136,$A33,'Per field'!$O$2:$O$136,"Only Flash")+COUNTIFS('Per field'!$B$2:$B$136,$A33,'Per field'!$O$2:$O$136,"Only Pro") -> 7 | H33: =IFERROR(D33/C33,"–") -> – | I33: =IFERROR((D33+E33)/C33,"–") -> – | J33: =IFERROR(AVERAGEIFS('Per field'!$P$2:$P$136,'Per field'!$B$2:$B$136,$A33),"–") -> –
A34: 2 Research context | B34: =COUNTIFS('Per field'!$B$2:$B$136,$A34,'Per field'!$O$2:$O$136,"<>Not in sheet") -> 13 | C34: =D34+E34+F34 -> 4 | D34: =COUNTIFS('Per field'!$B$2:$B$136,$A34,'Per field'!$O$2:$O$136,"Identical") -> 0 | E34: =COUNTIFS('Per field'!$B$2:$B$136,$A34,'Per field'!$O$2:$O$136,"Similar") -> 1 | F34: =COUNTIFS('Per field'!$B$2:$B$136,$A34,'Per field'!$O$2:$O$136,"Low") -> 3 | G34: =COUNTIFS('Per field'!$B$2:$B$136,$A34,'Per field'!$O$2:$O$136,"Only Flash")+COUNTIFS('Per field'!$B$2:$B$136,$A34,'Per field'!$O$2:$O$136,"Only Pro") -> 8 | H34: =IFERROR(D34/C34,"–") -> 0 | I34: =IFERROR((D34+E34)/C34,"–") -> 0.25 | J34: =IFERROR(AVERAGEIFS('Per field'!$P$2:$P$136,'Per field'!$B$2:$B$136,$A34),"–") -> 0.3775
A35: 3 Social media data | B35: =COUNTIFS('Per field'!$B$2:$B$136,$A35,'Per field'!$O$2:$O$136,"<>Not in sheet") -> 25 | C35: =D35+E35+F35 -> 5 | D35: =COUNTIFS('Per field'!$B$2:$B$136,$A35,'Per field'!$O$2:$O$136,"Identical") -> 0 | E35: =COUNTIFS('Per field'!$B$2:$B$136,$A35,'Per field'!$O$2:$O$136,"Similar") -> 2 | F35: =COUNTIFS('Per field'!$B$2:$B$136,$A35,'Per field'!$O$2:$O$136,"Low") -> 3 | G35: =COUNTIFS('Per field'!$B$2:$B$136,$A35,'Per field'!$O$2:$O$136,"Only Flash")+COUNTIFS('Per field'!$B$2:$B$136,$A35,'Per field'!$O$2:$O$136,"Only Pro") -> 5 | H35: =IFERROR(D35/C35,"–") -> 0 | I35: =IFERROR((D35+E35)/C35,"–") -> 0.4 | J35: =IFERROR(AVERAGEIFS('Per field'!$P$2:$P$136,'Per field'!$B$2:$B$136,$A35),"–") -> 0.426
A36: 4 AI methodology | B36: =COUNTIFS('Per field'!$B$2:$B$136,$A36,'Per field'!$O$2:$O$136,"<>Not in sheet") -> 25 | C36: =D36+E36+F36 -> 3 | D36: =COUNTIFS('Per field'!$B$2:$B$136,$A36,'Per field'!$O$2:$O$136,"Identical") -> 0 | E36: =COUNTIFS('Per field'!$B$2:$B$136,$A36,'Per field'!$O$2:$O$136,"Similar") -> 3 | F36: =COUNTIFS('Per field'!$B$2:$B$136,$A36,'Per field'!$O$2:$O$136,"Low") -> 0 | G36: =COUNTIFS('Per field'!$B$2:$B$136,$A36,'Per field'!$O$2:$O$136,"Only Flash")+COUNTIFS('Per field'!$B$2:$B$136,$A36,'Per field'!$O$2:$O$136,"Only Pro") -> 4 | H36: =IFERROR(D36/C36,"–") -> 0 | I36: =IFERROR((D36+E36)/C36,"–") -> 1 | J36: =IFERROR(AVERAGEIFS('Per field'!$P$2:$P$136,'Per field'!$B$2:$B$136,$A36),"–") -> 0.62
A37: 5 Graph/network | B37: =COUNTIFS('Per field'!$B$2:$B$136,$A37,'Per field'!$O$2:$O$136,"<>Not in sheet") -> 11 | C37: =D37+E37+F37 -> 0 | D37: =COUNTIFS('Per field'!$B$2:$B$136,$A37,'Per field'!$O$2:$O$136,"Identical") -> 0 | E37: =COUNTIFS('Per field'!$B$2:$B$136,$A37,'Per field'!$O$2:$O$136,"Similar") -> 0 | F37: =COUNTIFS('Per field'!$B$2:$B$136,$A37,'Per field'!$O$2:$O$136,"Low") -> 0 | G37: =COUNTIFS('Per field'!$B$2:$B$136,$A37,'Per field'!$O$2:$O$136,"Only Flash")+COUNTIFS('Per field'!$B$2:$B$136,$A37,'Per field'!$O$2:$O$136,"Only Pro") -> 1 | H37: =IFERROR(D37/C37,"–") -> – | I37: =IFERROR((D37+E37)/C37,"–") -> – | J37: =IFERROR(AVERAGEIFS('Per field'!$P$2:$P$136,'Per field'!$B$2:$B$136,$A37),"–") -> –
A38: 6 Evaluation | B38: =COUNTIFS('Per field'!$B$2:$B$136,$A38,'Per field'!$O$2:$O$136,"<>Not in sheet") -> 16 | C38: =D38+E38+F38 -> 0 | D38: =COUNTIFS('Per field'!$B$2:$B$136,$A38,'Per field'!$O$2:$O$136,"Identical") -> 0 | E38: =COUNTIFS('Per field'!$B$2:$B$136,$A38,'Per field'!$O$2:$O$136,"Similar") -> 0 | F38: =COUNTIFS('Per field'!$B$2:$B$136,$A38,'Per field'!$O$2:$O$136,"Low") -> 0 | G38: =COUNTIFS('Per field'!$B$2:$B$136,$A38,'Per field'!$O$2:$O$136,"Only Flash")+COUNTIFS('Per field'!$B$2:$B$136,$A38,'Per field'!$O$2:$O$136,"Only Pro") -> 9 | H38: =IFERROR(D38/C38,"–") -> – | I38: =IFERROR((D38+E38)/C38,"–") -> – | J38: =IFERROR(AVERAGEIFS('Per field'!$P$2:$P$136,'Per field'!$B$2:$B$136,$A38),"–") -> –
A39: 7 Findings | B39: =COUNTIFS('Per field'!$B$2:$B$136,$A39,'Per field'!$O$2:$O$136,"<>Not in sheet") -> 12 | C39: =D39+E39+F39 -> 2 | D39: =COUNTIFS('Per field'!$B$2:$B$136,$A39,'Per field'!$O$2:$O$136,"Identical") -> 0 | E39: =COUNTIFS('Per field'!$B$2:$B$136,$A39,'Per field'!$O$2:$O$136,"Similar") -> 0 | F39: =COUNTIFS('Per field'!$B$2:$B$136,$A39,'Per field'!$O$2:$O$136,"Low") -> 2 | G39: =COUNTIFS('Per field'!$B$2:$B$136,$A39,'Per field'!$O$2:$O$136,"Only Flash")+COUNTIFS('Per field'!$B$2:$B$136,$A39,'Per field'!$O$2:$O$136,"Only Pro") -> 9 | H39: =IFERROR(D39/C39,"–") -> 0 | I39: =IFERROR((D39+E39)/C39,"–") -> 0 | J39: =IFERROR(AVERAGEIFS('Per field'!$P$2:$P$136,'Per field'!$B$2:$B$136,$A39),"–") -> 0.235
A40: 8 Ethics & reproducibility | B40: =COUNTIFS('Per field'!$B$2:$B$136,$A40,'Per field'!$O$2:$O$136,"<>Not in sheet") -> 15 | C40: =D40+E40+F40 -> 1 | D40: =COUNTIFS('Per field'!$B$2:$B$136,$A40,'Per field'!$O$2:$O$136,"Identical") -> 1 | E40: =COUNTIFS('Per field'!$B$2:$B$136,$A40,'Per field'!$O$2:$O$136,"Similar") -> 0 | F40: =COUNTIFS('Per field'!$B$2:$B$136,$A40,'Per field'!$O$2:$O$136,"Low") -> 0 | G40: =COUNTIFS('Per field'!$B$2:$B$136,$A40,'Per field'!$O$2:$O$136,"Only Flash")+COUNTIFS('Per field'!$B$2:$B$136,$A40,'Per field'!$O$2:$O$136,"Only Pro") -> 3 | H40: =IFERROR(D40/C40,"–") -> 1 | I40: =IFERROR((D40+E40)/C40,"–") -> 1 | J40: =IFERROR(AVERAGEIFS('Per field'!$P$2:$P$136,'Per field'!$B$2:$B$136,$A40),"–") -> 1
A41: 9 Notes | B41: =COUNTIFS('Per field'!$B$2:$B$136,$A41,'Per field'!$O$2:$O$136,"<>Not in sheet") -> 4 | C41: =D41+E41+F41 -> 0 | D41: =COUNTIFS('Per field'!$B$2:$B$136,$A41,'Per field'!$O$2:$O$136,"Identical") -> 0 | E41: =COUNTIFS('Per field'!$B$2:$B$136,$A41,'Per field'!$O$2:$O$136,"Similar") -> 0 | F41: =COUNTIFS('Per field'!$B$2:$B$136,$A41,'Per field'!$O$2:$O$136,"Low") -> 0 | G41: =COUNTIFS('Per field'!$B$2:$B$136,$A41,'Per field'!$O$2:$O$136,"Only Flash")+COUNTIFS('Per field'!$B$2:$B$136,$A41,'Per field'!$O$2:$O$136,"Only Pro") -> 2 | H41: =IFERROR(D41/C41,"–") -> – | I41: =IFERROR((D41+E41)/C41,"–") -> – | J41: =IFERROR(AVERAGEIFS('Per field'!$P$2:$P$136,'Per field'!$B$2:$B$136,$A41),"–") -> –
A42: Not in schema | B42: =COUNTIFS('Per field'!$B$2:$B$136,$A42,'Per field'!$O$2:$O$136,"<>Not in sheet") -> 1 | C42: =D42+E42+F42 -> 1 | D42: =COUNTIFS('Per field'!$B$2:$B$136,$A42,'Per field'!$O$2:$O$136,"Identical") -> 1 | E42: =COUNTIFS('Per field'!$B$2:$B$136,$A42,'Per field'!$O$2:$O$136,"Similar") -> 0 | F42: =COUNTIFS('Per field'!$B$2:$B$136,$A42,'Per field'!$O$2:$O$136,"Low") -> 0 | G42: =COUNTIFS('Per field'!$B$2:$B$136,$A42,'Per field'!$O$2:$O$136,"Only Flash")+COUNTIFS('Per field'!$B$2:$B$136,$A42,'Per field'!$O$2:$O$136,"Only Pro") -> 0 | H42: =IFERROR(D42/C42,"–") -> 1 | I42: =IFERROR((D42+E42)/C42,"–") -> 1 | J42: =IFERROR(AVERAGEIFS('Per field'!$P$2:$P$136,'Per field'!$B$2:$B$136,$A42),"–") -> 1
...

Sheet Other datasets - fields
A1: Dataset | B1: # | C1: Theme | D1: Field | E1: Status | F1: Similarity | G1: Value A | H1: Value B
A2: Summary_Insights / Sheet1 | B2: 1 | C2: 7 Findings | D2: implications_for_heritage_management | E2: Low | F2: 0.33 | G2: ["Destination managers should customize promotional content to align with visitor perceptions, which are more oriented to 'Exceptionality' and 'Attractiveness'.", 'UNESCO experts should consider the discrepancy between their official descriptions and visitor perceptions to better communicate the intangible meanings of World Heritage.', 'Experts should consider how various UNESCO concepts relate to the identified personality categories when developing different WH personality strategies.'] | H2: ['UNESCO experts should further analyze the way in which visitors perceive intangible WH meanings.', 'Experts should consider how various UNESCO concepts relate to WH categories as reported in this study when developing a different WH personality strategy.']
A3: Summary_Insights / Sheet1 | B3: 2 | C3: 7 Findings | D3: methodological_contributions | E3: Low | F3: 0.25 | G3: ['A new three-phase model for identifying and measuring brand personality from digital text data: (1) item generation; (2) item refinement; and (3) word embedding and clustering.', 'Development of a 192-item World Heritage Site personality dictionary.', 'The first study to apply word-embedding techniques to categorize brand personality items based on their correlated similarities.'] | H3: ['Designed a novel method for constructing context-driven Brand Personality categories through a multi-disciplinary approach.', 'Developed a three-step approach: generating items; refining items; and word embedding and clustering items.', "Proposed a 'BP Word Embedding Model' that applies text-mining and machine learning.", 'Offered a new technique for defining BP categories extracted for the first time entirely from digital texts.', 'Adopted the word-embedding technique to categorize items and assist in defining the similarity between WH personality items.']
A4: Summary_Insights / Sheet1 | B4: 3 | C4: 7 Findings | D4: empirical_contributions | E4: Low | F4: 0.17 | G4: ['Analysis of a large corpus of text including descriptions of all 1,121 UNESCO WHSs and 9,920 user-generated reviews from Tripadvisor.', 'The identification of five core personality categories for WHSs and their distribution across expert and visitor texts.'] | H4: ['Identified a 192-item WHS personality dictionary organized into five clusters: Exceptionality; Attractiveness; Identification; Responsibility; and Prominence.', 'The results show that UNESCO strongly associates WHSs with the attributes of Attractiveness and Identification.', 'Tripadvisor visitors attributed Exceptionality to 55.59% of WHSs.']
A5: Summary_Insights / Sheet1 | B5: 4 | C5: 7 Findings | D5: conceptual_contributions | E5: Low | F5: 0.29 | G5: ['Extends the brand personality concept to World Heritage Sites.', "Proposes a new method to construct context-driven brand personality categories, addressing limitations of generalizability in previous scales like Aaker's."] | H5: ['Extends the Brand Personality (BP) concept to World Heritage Sites (WHSs) in a novel, data-driven way.', "Provides a framework for understanding the 'brand culture' of WHSs by comparing expert (sender) and visitor (receiver) perceptions.", 'Argues for a context-driven approach to defining personality scales, moving beyond generalized scales.']
A6: Summary_Insights / Sheet1 | B6: 5 | C6: 7 Findings | D6: limitations_or_challenges | E6: Low | F6: 0.44 | G6: ['The amount of data available was a limitation, which forced the use of a pre-trained language model (Fasttext) instead of training a custom model on subject-specific data.', 'The sample of visitor reviews was limited to those written in English, which may not represent the views of all visitors.'] | H6: ['The sample was limited to reviews written in English.', 'Most of the WHSs in Iran were not on Tripadvisor, limiting data collection.', 'The amount of data available forced the authors to use a pre-trained language model rather than training their own.', 'Inability to generate a custom language model due to insufficient sample size.']
A7: Summary_Insights / Sheet1 | B7: 6 | C7: 8 Ethics & reproducibility | D7: privacy_and_data_protection | E7: Empty in both
A8: Summary_Insights / Sheet1 | B8: 7 | C8: 8 Ethics & reproducibility | D8: bias_fairness_representativeness | E8: Identical | F8: 1 | G8: ['The sample was limited to reviews written in English, although visitors were from many countries, reducing segment bias.'] | H8: ['The sample was limited to reviews written in English, although visitors were from many countries, reducing segment bias.']
A9: Summary_Insights / Sheet1 | B9: 8 | C9: 8 Ethics & reproducibility | D9: ethical_frameworks_or_guidelines | E9: Empty in both
A10: Summary_Insights / Sheet1 | B10: 9 | C10: 8 Ethics & reproducibility | D10: cultural_community_considerations | E10: Empty in both
A11: Summary_Insights / Sheet1 | B11: 10 | C11: 8 Ethics & reproducibility | D11: legal_or_policy_constraints | E11: Empty in both
A12: Summary_Insights / Sheet1 | B12: 11 | C12: 8 Ethics & reproducibility | D12: risks_to_people_or_heritage | E12: Empty in both
A13: UNESCO_to_Map / Sheet1 | B13: 1 | D13: overall_status | E13: Identical | F13: 1 | G13: UNESCO | H13: UNESCO
A14: UNESCO_to_Map / Sheet1 | B14: 2 | D14: unesco_site_names | E14: Similar | F14: 0.8 | G14: Cathedral, Alcázar and Archivo de Indias in Seville | H14: Cathedral, Alcázar and Archivo de Indias in Seville; Historic Centre of Macao
A15: UNESCO_to_Map / Sheet1 | B15: 3 | D15: (unnamed column F) | E15: Similar | F15: 0.78 | G15: all 1,121 UNESCO World Heritage Sites (WHSs); the cathedral, the Real Alcázar and the Archivo General de Indias in Seville | H15: the cathedral, the Real Alcázar and the Archivo General de Indias in Seville
A16: UNESCO_to_Map / Sheet1 | B16: 4 | D16: (unnamed column G) | E16: Similar | F16: 0.62 | G16: China; India; Japan; Asia and Pacific region; Europe; France; Germany; Italy; Spain; Iran | H16: China; India; Japan; France; Germany; Italy; Spain; Asia and Pacific region; Europe; Iran; German cultural context; Croatian brands; Macau; Nepal; West Bengal, India; Bangladesh
A17: UNESCO_to_Map / Sheet1 | B17: 5 | D17: is_referenced_by_count | E17: Only A | F17: 0 | G17: 6
A18: UNESCO_to_Map / Sheet1 | B18: 6 | D18: (unnamed column I) | E18: Identical | F18: 1 | G18: 0 | H18: 0
A19: UNESCO_to_Map / Sheet1 | B19: 7 | D19: unesco_site_names (column J) | E19: Identical | F19: 1 | G19: Cathedral, Alcázar and Archivo de Indias in Seville | H19: Cathedral, Alcázar and Archivo de Indias in Seville
A20: UNESCO_to_Map / Sheet1 | B20: 8 | D20: (unnamed column K) | E20: Identical | F20: 1 | G20: 1 | H20: 1
A21: UNESCO_to_Map / Sheet1 | B21: 9 | D21: unesco_site_names_old | E21: Similar | F21: 0.8 | G21: Cathedral, Alcázar and Archivo de Indias in Seville | H21: Cathedral, Alcázar and Archivo de Indias in Seville; Historic Centre of Macao
A22: UNESCO_to_Map / Sheet1 | B22: 10 | D22: (unnamed column M) | E22: Low | F22: 0 | G22: 1 | H22: 2
A23: UNESCO_to_Map / Sheet1 | B23: 11 | D23: iou_score | E23: Low | F23: 0 | G23: 1 | H23: 0.5
A24: UNESCO_to_Map / Sheet1 | B24: 12 | D24: unesco_places | E24: Similar | F24: 0.96 | G24: the cathedral, the Real Alcázar and the Archivo General de Indias in Seville | H24: Macau | the cathedral, the Real Alcázar and the Archivo General de Indias in Seville
A25: UNESCO_to_Map / Sheet1 | B25: 13 | D25: unesco_exact | E25: Identical | F25: 1 | G25: 0 | H25: 0
A26: UNESCO_to_Map / Sheet1 | B26: 14 | D26: tentative_site_names | E26: Empty in both
A27: UNESCO_to_Map / Sheet1 | B27: 15 | D27: City_Country_Pairs | E27: Identical | F27: 1 | G27: Girona (Spain) | H27: Girona (Spain)
A28: UNESCO_to_Map / Sheet1 | B28: 16 | D28: (unnamed column S) | E28: Empty in both
A29: UNESCO_to_Map / Sheet1 | B29: 17 | D29: (unnamed column T) | E29: Low | F29: 0.15 | G29: Department of Business, Universitat de Girona, Girona, Spain; Department of Business, Universitat de Girona, Girona, Spain; Department of Art and History of Art, Universitat de Girona, Girona, Spain | H29: Univ Girona, Fac Tourism, Dept Business, Girona, Spain; Univ Girona, Fac Tourism, Dept Art & Hist Art, Girona, Spain; Univ Girona, Fac Tourism, Dept Hist Art Res Line Cultural Tourism & Heritage, Placa Ferrater Mora 1, Girona Despatx 433, Girona 17004, Spain
A30: UNESCO_to_Map / Sheet1 | B30: 18 | D30: Extract_raw | E30: Identical | F30: 1 | G30: TripAdvisor, 🔚 | H30: TripAdvisor, 🔚
A31: UNESCO_to_Map / Sheet1 | B31: 19 | D31: Extract | E31: Empty in both
A32: UNESCO_to_Map / To Map | B32: 1 | D32: unesco_site_names | E32: Identical | F32: 1 | G32: Cathedral, Alcázar and Archivo de Indias in Seville | H32: Cathedral, Alcázar and Archivo de Indias in Seville
A33: UNESCO_to_Map / To Map | B33: 2 | D33: unesco_exact | E33: Identical | F33: 1 | G33: 0 | H33: 0
A34: UNESCO_to_Map / To Map | B34: 3 | D34: City_Country_Pairs | E34: Identical | F34: 1 | G34: Girona (Spain) | H34: Girona (Spain)
A35: Binary_encodings.csv | B35: 1 | C35: platform | D35: platform_twitter | E35: Identical | F35: 1 | G35: 0 | H35: 0
A36: Binary_encodings.csv | B36: 2 | C36: platform | D36: platform_flickr | E36: Identical | F36: 1 | G36: 0 | H36: 0
A37: Binary_encodings.csv | B37: 3 | C37: platform | D37: platform_instagram | E37: Identical | F37: 1 | G37: 0 | H37: 0
A38: Binary_encodings.csv | B38: 4 | C38: platform | D38: platform_facebook | E38: Identical | F38: 1 | G38: 0 | H38: 0
A39: Binary_encodings.csv | B39: 5 | C39: platform | D39: platform_tripadvisor | E39: Identical | F39: 1 | G39: 1 | H39: 1
A40: Binary_encodings.csv | B40: 6 | C40: platform | D40: platform_social_media_general | E40: Identical | F40: 1 | G40: 0 | H40: 0
...

Sheet Other datasets - summary
A1: Agreement between record A and record B in the other processed datasets
A2: Dataset | B2: Fields | C2: Filled | D2: Identical | E2: Similar | F2: Low | G2: Only one record | H2: Identical rate | I2: Identical or similar | J2: Mean similarity | K2: Note
A3: Summary_Insights / Sheet1 | B3: =COUNTIFS('Other datasets - fields'!$A$2:$A$138,$A3) -> 11 | C3: =D3+E3+F3+G3 -> 6 | D3: =COUNTIFS('Other datasets - fields'!$A$2:$A$138,$A3,'Other datasets - fields'!$E$2:$E$138,"Identical") -> 1 | E3: =COUNTIFS('Other datasets - fields'!$A$2:$A$138,$A3,'Other datasets - fields'!$E$2:$E$138,"Similar") -> 0 | F3: =COUNTIFS('Other datasets - fields'!$A$2:$A$138,$A3,'Other datasets - fields'!$E$2:$E$138,"Low") -> 5 | G3: =COUNTIFS('Other datasets - fields'!$A$2:$A$138,$A3,'Other datasets - fields'!$E$2:$E$138,"Only A")+COUNTIFS('Other datasets - fields'!$A$2:$A$138,$A3,'Other datasets - fields'!$E$2:$E$138,"Only B") -> 0 | H3: =IFERROR(D3/C3,"–") -> 0.16666667 | I3: =IFERROR((D3+E3)/C3,"–") -> 0.16666667 | J3: =IFERROR(AVERAGEIFS('Other datasets - fields'!$F$2:$F$138,'Other datasets - fields'!$A$2:$A$138,$A3),"–") -> 0.41333333 | K3: Same content as the Pro findings fields
A4: UNESCO_to_Map / Sheet1 | B4: =COUNTIFS('Other datasets - fields'!$A$2:$A$138,$A4) -> 19 | C4: =D4+E4+F4+G4 -> 16 | D4: =COUNTIFS('Other datasets - fields'!$A$2:$A$138,$A4,'Other datasets - fields'!$E$2:$E$138,"Identical") -> 7 | E4: =COUNTIFS('Other datasets - fields'!$A$2:$A$138,$A4,'Other datasets - fields'!$E$2:$E$138,"Similar") -> 5 | F4: =COUNTIFS('Other datasets - fields'!$A$2:$A$138,$A4,'Other datasets - fields'!$E$2:$E$138,"Low") -> 3 | G4: =COUNTIFS('Other datasets - fields'!$A$2:$A$138,$A4,'Other datasets - fields'!$E$2:$E$138,"Only A")+COUNTIFS('Other datasets - fields'!$A$2:$A$138,$A4,'Other datasets - fields'!$E$2:$E$138,"Only B") -> 1 | H4: =IFERROR(D4/C4,"–") -> 0.4375 | I4: =IFERROR((D4+E4)/C4,"–") -> 0.75 | J4: =IFERROR(AVERAGEIFS('Other datasets - fields'!$F$2:$F$138,'Other datasets - fields'!$A$2:$A$138,$A4),"–") -> 0.694375 | K4: Sheet has unnamed and repeated column headers; unnamed columns are shown by their column letter
A5: UNESCO_to_Map / To Map | B5: =COUNTIFS('Other datasets - fields'!$A$2:$A$138,$A5) -> 3 | C5: =D5+E5+F5+G5 -> 3 | D5: =COUNTIFS('Other datasets - fields'!$A$2:$A$138,$A5,'Other datasets - fields'!$E$2:$E$138,"Identical") -> 3 | E5: =COUNTIFS('Other datasets - fields'!$A$2:$A$138,$A5,'Other datasets - fields'!$E$2:$E$138,"Similar") -> 0 | F5: =COUNTIFS('Other datasets - fields'!$A$2:$A$138,$A5,'Other datasets - fields'!$E$2:$E$138,"Low") -> 0 | G5: =COUNTIFS('Other datasets - fields'!$A$2:$A$138,$A5,'Other datasets - fields'!$E$2:$E$138,"Only A")+COUNTIFS('Other datasets - fields'!$A$2:$A$138,$A5,'Other datasets - fields'!$E$2:$E$138,"Only B") -> 0 | H5: =IFERROR(D5/C5,"–") -> 1 | I5: =IFERROR((D5+E5)/C5,"–") -> 1 | J5: =IFERROR(AVERAGEIFS('Other datasets - fields'!$F$2:$F$138,'Other datasets - fields'!$A$2:$A$138,$A5),"–") -> 1
A6: Binary_encodings.csv | B6: =COUNTIFS('Other datasets - fields'!$A$2:$A$138,$A6) -> 104 | C6: =D6+E6+F6+G6 -> 104 | D6: =COUNTIFS('Other datasets - fields'!$A$2:$A$138,$A6,'Other datasets - fields'!$E$2:$E$138,"Identical") -> 103 | E6: =COUNTIFS('Other datasets - fields'!$A$2:$A$138,$A6,'Other datasets - fields'!$E$2:$E$138,"Similar") -> 0 | F6: =COUNTIFS('Other datasets - fields'!$A$2:$A$138,$A6,'Other datasets - fields'!$E$2:$E$138,"Low") -> 1 | G6: =COUNTIFS('Other datasets - fields'!$A$2:$A$138,$A6,'Other datasets - fields'!$E$2:$E$138,"Only A")+COUNTIFS('Other datasets - fields'!$A$2:$A$138,$A6,'Other datasets - fields'!$E$2:$E$138,"Only B") -> 0 | H6: =IFERROR(D6/C6,"–") -> 0.99038462 | I6: =IFERROR((D6+E6)/C6,"–") -> 0.99038462 | J6: =IFERROR(AVERAGEIFS('Other datasets - fields'!$F$2:$F$138,'Other datasets - fields'!$A$2:$A$138,$A6),"–") -> 0.99038462 | K6: Binary 0/1 codes; a 0 counts as a filled value, so 0-0 is an agreement. Only task_topic_modeling differs (A=1, B=0)
